<?xml version='1.0'?>

<robot name="my_robot" xmlns:xacro="http://www.ros.org/wiki/xacro">
  <xacro:include filename="$(find my_robot)/urdf/my_robot.gazebo" />
  <link name="robot_footprint"></link>

  <joint name="robot_footprint_joint" type="fixed">
    <origin xyz="0 0 0" rpy="0 0 0" />
    <parent link="robot_footprint" />
    <child link="chassis" />
  </joint>

                                                                    <!-- CHASSIS -->
  <link name="chassis">
    <pose>0 0 0.1 0 0 0</pose>

    <inertial>
      <mass value="15.0"/>
      <origin xyz="0.0 0 0" rpy="0 0 0" />
      <inertia
        ixx="0.1" ixy="0" ixz="0"
        iyy="0.1" iyz="0"
        izz="0.1"
      />
    </inertial>

    <collision name="collision">
      <origin xyz="0 0 0" rpy="0 0 0" />
      <geometry>
        <box size=".6 .4 .1" />
      </geometry>
    </collision>

    <visual name='chassis_visual'>
      <origin xyz="0 0 0" rpy="0 0 0" />
      <geometry>
        <box size=".6 .4 .1" />
      </geometry>
    </visual>

   <collision name="back_caster_collision">
      <origin xyz="-0.2 0 -0.05" rpy="0 0 0" />
      <geometry>
        <sphere radius="0.0499" />
      </geometry>
    </collision>

   <visual name="back_caster_visual">
      <origin xyz="-0.2 0 -0.05" rpy="0 0 0" />
      <geometry>
        <sphere radius="0.0499" />
      </geometry>
    </visual>

   <collision name="front_caster_collision">
      <origin xyz="0.2 0 -0.05" rpy="0 0 0" />
      <geometry>
        <sphere radius="0.0499" />
      </geometry>
    </collision>

   <visual name="front_caster_visual">
      <origin xyz="0.2 0 -0.05" rpy="0 0 0" />
      <geometry>
        <sphere radius="0.0499" />
      </geometry>
    </visual>
  </link>


                                                                <!-- LEFT WHEEL -->
  <link name="left_wheel">
    <inertial>
        <mass value="5" />
        <origin xyz="0 0 0" rpy="0 1.5707 1.5707" />
        <inertia
            ixx="0.1" ixy="0" ixz="0"
            iyy="0.1" iyz="0"
            izz="0.1" />
        </inertial>
    <visual name="left_wheel_visual">
        <origin xyz="0 0 0" rpy="0 1.5707 1.5707"/>
        <geometry>
            <cylinder radius="0.1" length="0.05" />
        </geometry>
    </visual>
    <collision name="left_wheel_collision">
        <origin xyz="0 0 0" rpy="0 1.5707 1.5707"/>
        <geometry>
            <cylinder radius="0.1" length="0.05" />
        </geometry>
    </collision>
  </link>
                                                                <!--RIGHT WHEEL -->
  <link name="right_wheel">
    <inertial>
        <mass value="5" />
        <origin xyz="0 0 0" rpy="0 1.5707 1.5707" />
        <inertia
            ixx="0.1" ixy="0" ixz="0"
            iyy="0.1" iyz="0"
            izz="0.1" />
        </inertial>
    <visual name="right_wheel_visual">
        <origin xyz="0 0 0" rpy="0 1.5707 1.5707"/>
        <geometry>
            <cylinder radius="0.1" length="0.05" />
        </geometry>
    </visual>
    <collision name="right_wheel_collision">
        <origin xyz="0 0 0" rpy="0 1.5707 1.5707"/>
        <geometry>
            <cylinder radius="0.1" length="0.05" />
        </geometry>
    </collision>
  </link>
  


<link name="lf_support">
    <inertial>
        <mass value="0.5" />
        <origin xyz="0 0 0" rpy="0 0 0" />
        <inertia
            ixx="0.1" ixy="0" ixz="0"
            iyy="0.1" iyz="0"
            izz="0.1" />
        </inertial>
    <visual name="lf_support_visual">
        <origin xyz="0 0 0" rpy="0 0 0"/>
        <geometry>
            <cylinder radius="0.015" length="0.12" />
        </geometry>
    </visual>
    <collision name="lf_support_collision">
        <origin xyz="0 0 0" rpy="0 0 0"/>
        <geometry>
            <cylinder radius="0.015" length="0.12" />
        </geometry>
    </collision>
  </link>

  <joint type="fixed" name="lf_d_support_joint">
      <origin xyz="0.1 0.15 0.1" rpy="0 0 0" />
      <child link="lf_support" />
      <parent link="chassis" />
      <axis xyz="0 0 0" rpy="0 0 0" />
  </joint>





<link name="lb_support">
    <inertial>
        <mass value="0.5" />
        <origin xyz="0 0 0" rpy="0 0 0" />
        <inertia
            ixx="0.1" ixy="0" ixz="0"
            iyy="0.1" iyz="0"
            izz="0.1" />
        </inertial>
    <visual name="lb_support_visual">
        <origin xyz="0 0 0" rpy="0 0 0"/>
        <geometry>
            <cylinder radius="0.015" length="0.12" />
        </geometry>
    </visual>
    <collision name="lb_support_collision">
        <origin xyz="0 0 0" rpy="0 0 0"/>
        <geometry>
            <cylinder radius="0.015" length="0.12" />
        </geometry>
    </collision>
  </link>

  <joint type="fixed" name="lb_d_support_joint">
      <origin xyz="-0.25 0.15 0.1" rpy="0 0 0" />
      <child link="lb_support" />
      <parent link="chassis" />
      <axis xyz="0 0 0" rpy="0 0 0" />
  </joint>




<link name="rf_support">
    <inertial>
        <mass value="0.5" />
        <origin xyz="0 0 0" rpy="0 0 0" />
        <inertia
            ixx="0.1" ixy="0" ixz="0"
            iyy="0.1" iyz="0"
            izz="0.1" />
        </inertial>
    <visual name="rf_support_visual">
        <origin xyz="0 0 0" rpy="0 0 0"/>
        <geometry>
            <cylinder radius="0.015" length="0.12" />
        </geometry>
    </visual>
    <collision name="rf_support_collision">
        <origin xyz="0 0 0" rpy="0 0 0"/>
        <geometry>
            <cylinder radius="0.015" length="0.12" />
        </geometry>
    </collision>
  </link>

  <joint type="fixed" name="rf_d_support_joint">
      <origin xyz="0.1 -0.15 0.1" rpy="0 0 0" />
      <child link="rf_support" />
      <parent link="chassis" />
      <axis xyz="0 0 0" rpy="0 0 0" />
  </joint>



<link name="rb_support">
    <inertial>
        <mass value="0.5" />
        <origin xyz="0 0 0" rpy="0 0 0" />
        <inertia
            ixx="0.1" ixy="0" ixz="0"
            iyy="0.1" iyz="0"
            izz="0.1" />
        </inertial>
    <visual name="rb_support_visual">
        <origin xyz="0 0 0" rpy="0 0 0"/>
        <geometry>
            <cylinder radius="0.015" length="0.12" />
        </geometry>
    </visual>
    <collision name="rb_support_collision">
        <origin xyz="0 0 0" rpy="0 0 0"/>
        <geometry>
            <cylinder radius="0.015" length="0.12" />
        </geometry>
    </collision>
  </link>

  <joint type="fixed" name="rb_d_support_joint">
      <origin xyz="-0.25 -0.15 0.1" rpy="0 0 0" />
      <child link="rb_support" />
      <parent link="chassis" />
      <axis xyz="0 0 0" rpy="0 0 0" />
  </joint>



<link name="upper_chassis">
    <pose>0 0 0.1 0 0 0</pose>

    <inertial>
      <mass value="5.0"/>
      <origin xyz="0.0 0 0" rpy="0 0 0" />
      <inertia
        ixx="0.1" ixy="0" ixz="0"
        iyy="0.1" iyz="0"
        izz="0.1"
      />
    </inertial>

    <collision name="upper_chassis_collision">
      <origin xyz="0 0 0" rpy="0 0 0" />
      <geometry>
        <box size=".4 .4 .04" />
      </geometry>
    </collision>

    <visual name='upper_chassis_visual'>
      <origin xyz="0 0 0" rpy="0 0 0" />
      <geometry>
        <box size=".4 .4 .04" />
      </geometry>
    </visual>
  </link>

  <joint type="fixed" name="lf_u_support">
      <origin xyz="-0.08 0 0.15" rpy="0 0 0" />
      <child link="upper_chassis" />
      <parent link="chassis" />
      <axis xyz="0 1 0" rpy="0 0 0" />
  </joint>



  <link name="camera">
      <inertial>
          <mass value="0.1" />
          <origin xyz="0 0 0" rpy="0 0 0" />
          <inertia
              ixx="1e-6" ixy="0" ixz="0"
              iyy="1e-6" iyz="0"
              izz="1e-6"
            />
      </inertial>
      
      <visual name="camera_visual">
          <origin xyz="0 0 0" rpy="0 0 0"/>
          <geometry>
              <box size="0.05 0.05 0.05" />
          </geometry>
      </visual>
      
      <collision name="camera_collision">
          <origin xyz="0 0 0" rpy="0 0 0"/>
          <geometry>
              <box size="0.05 0.05 0.05" />
          </geometry>
      </collision>
      
  </link>
  
  <link name="hokuyo">
      <inertial>
          <mass value="1e-5" />
          <origin xyz="0 0 0" rpy="0 0 0" />
          <inertia
              ixx="1e-6" ixy="0" ixz="0"
              iyy="1e-6" iyz="0"
              izz="1e-6"
              />
      </inertial>
      <visual name="hokuyo_visual" >
          <origin xyz="0 0 0" rpy="0 0 0" />
          <geometry>
              <mesh filename="package://my_robot/meshes/hokuyo.dae" />
          </geometry>
      </visual>
      <collision name="hokuyo_collision">
          <origin xyz="0 0 0" rpy="0 0 0" />
              <geometry>
                  <box size="0.1 0.1 0.1" />
              </geometry>
      </collision>
  </link>
  <joint type="continuous" name="left_wheel_hinge">
      <origin xyz="0 0.25 0" rpy="0 0 0" />
      <child link="left_wheel" />
      <parent link="chassis" />
      <axis xyz="0 1 0" rpy="0 0 0" />
      <limit effort="10000" velocity="1000" />
      <dynamics damping="1.0" friction="1.0" />
  </joint>
  
  <joint type="continuous" name="right_wheel_hinge">
      <origin xyz="0 -0.25 0" rpy="0 0 0" />
      <child link="right_wheel" />
      <parent link="chassis" />
      <axis xyz="0 1 0" rpy="0 0 0" />
      <limit effort="10000" velocity="1000" />
      <dynamics damping="1.0" friction="1.0" />
  </joint>
  
  <joint type="fixed" name="camera_joint">
      <origin xyz="0.3 0 0" rpy="0 0 0" />
      <child link="camera" />
      <parent link="chassis" />
      <axis xyz="0 1 0" rpy="0 0 0" />
  </joint>
  
  <joint type="fixed" name="hokuyo_joint">
      <origin xyz="0.05 0 0.2" rpy="0 0 0" />
      <child link="hokuyo" />
      <parent link="chassis" />
      <axis xyz="0 1 0" rpy="0 0 0" />
  </joint>

  <gazebo reference="left_wheel">
    <material>Gazebo/Black</material>
  </gazebo>
  <gazebo reference="right_wheel">
    <material>Gazebo/Black</material>
  </gazebo>
  <gazebo reference="chassis">
    <material>Gazebo/White</material>
  </gazebo>
  <gazebo reference="lf_support">
    <material>Gazebo/Black</material>
  </gazebo>
  <gazebo reference="lb_support">
    <material>Gazebo/Black</material>
  </gazebo>
  <gazebo reference="rb_support">
    <material>Gazebo/Black</material>
  </gazebo>
  <gazebo reference="rf_support">
    <material>Gazebo/Black</material>
  </gazebo>
  <gazebo reference="upper_chassis">
    <material>Gazebo/White</material>
  </gazebo>
  <gazebo reference="camera">
    <material>Gazebo/Red</material>
  </gazebo>
</robot>
